2023-04-01 11:27:30,282 : INFO : root : Loading config.
2023-04-01 11:27:30,683 : INFO : ConfigProcessor : Config spec file cache created: /var/folders/0y/x6b2lmrx6vq3nhkjncz48nhc0000gn/T/config_spec.mpf_cache
2023-04-01 11:27:30,684 : INFO : YamlMultifileConfigLoader : Machine config file #1: config.yaml
2023-04-01 11:27:30,684 : INFO : ConfigProcessor : Loading config from cache: /var/folders/0y/x6b2lmrx6vq3nhkjncz48nhc0000gn/T/28c67afebeedf0bcd540f5dc9898a885.mpf_cache
2023-04-01 11:27:30,730 : INFO : ConfigProcessor : Loading config from cache: /var/folders/0y/x6b2lmrx6vq3nhkjncz48nhc0000gn/T/03cea1619b79a61f4f0eef3c59cdaa46.mpf_cache
2023-04-01 11:27:30,730 : INFO : ConfigProcessor : Loading config from cache: /var/folders/0y/x6b2lmrx6vq3nhkjncz48nhc0000gn/T/d3948d842c6309f14ab557c3c72320d0.mpf_cache
2023-04-01 11:27:30,731 : INFO : ConfigProcessor : Loading config from cache: /var/folders/0y/x6b2lmrx6vq3nhkjncz48nhc0000gn/T/a37a2141962f60258a07880b3484644a.mpf_cache
2023-04-01 11:27:30,732 : INFO : Machine : Mission Pinball Framework Core Engine v0.56.1.dev4
2023-04-01 11:27:30,732 : INFO : Machine : Command line arguments: {'no_load_cache': False, 'create_config_cache': True, 'bcp': False, 'configfile': ['config.yaml'], 'force_assets_load': False, 'jsonlogging': False, 'logfile': 'logs/2023-04-01-11-27-30-mpf-Tanners-MacBook-Pro-2.local.log', 'pause': False, 'production': False, 'text_ui': True, 'loglevel': 15, 'consoleloglevel': 20, 'force_platform': None, 'syslog_address': None, 'mc_file_name': None, 'no_sound': False}
2023-04-01 11:27:30,732 : INFO : Machine : MPF path: /Users/tpetch/.local/pipx/venvs/mpf/lib/python3.9/site-packages/mpf
2023-04-01 11:27:30,732 : INFO : Machine : Machine path: /Users/tpetch/Documents/trashland_3
2023-04-01 11:27:30,732 : INFO : Machine : Platform: darwin
2023-04-01 11:27:30,732 : INFO : Machine : Python executable location: /Users/tpetch/.local/pipx/venvs/mpf/bin/python
2023-04-01 11:27:30,732 : INFO : Machine : Python version: 3.9.13 (64-bit)
2023-04-01 11:27:30,738 : INFO : Machine : Initialise MPF.
2023-04-01 11:27:30,795 : INFO : [NET] : Trying to connect to /dev/tty.usbmodem14101 at 921600bps
2023-04-01 11:27:30,795 : ERROR : [NET] : Failed to connect to any of the specified ports.
2023-04-01 11:27:30,796 : INFO : Machine : Shutting down...
2023-04-01 11:27:30,796 : INFO : EventManager : Event: ======'shutdown'====== Args={}
2023-04-01 11:27:30,898 : ERROR : Machine : Failed to initialise MPF
Traceback (most recent call last):
  File "/Users/tpetch/.local/pipx/venvs/mpf/lib/python3.9/site-packages/mpf/platforms/fast/fast.py", line 243, in _connect_to_hardware
    await communicator.connect()
  File "/Users/tpetch/.local/pipx/venvs/mpf/lib/python3.9/site-packages/mpf/platforms/fast/communicators/base.py", line 98, in connect
    raise SerialException("Could not connect to any of the specified ports.")
serial.serialutil.SerialException: Could not connect to any of the specified ports.

The above exception was the direct cause of the following exception:

Traceback (most recent call last):
  File "/Users/tpetch/.local/pipx/venvs/mpf/lib/python3.9/site-packages/mpf/core/machine.py", line 679, in initialise_mpf
    raise init.exception()
  File "/Users/tpetch/.local/pipx/venvs/mpf/lib/python3.9/site-packages/mpf/core/machine.py", line 246, in initialise
    await self.initialise_core_and_hardware()
  File "/Users/tpetch/.local/pipx/venvs/mpf/lib/python3.9/site-packages/mpf/core/machine.py", line 242, in initialise_core_and_hardware
    await self._initialize_platforms()
  File "/Users/tpetch/.local/pipx/venvs/mpf/lib/python3.9/site-packages/mpf/core/machine.py", line 333, in _initialize_platforms
    result.result()
  File "/Users/tpetch/.local/pipx/venvs/mpf/lib/python3.9/site-packages/mpf/platforms/fast/fast.py", line 113, in initialize
    await self._connect_to_hardware()
  File "/Users/tpetch/.local/pipx/venvs/mpf/lib/python3.9/site-packages/mpf/platforms/fast/fast.py", line 245, in _connect_to_hardware
    raise MpfRuntimeError("Could not open serial port {}. Is something else connected to the port? "
mpf.exceptions.runtime_error.MpfRuntimeError: Runtime Error in FAST: Could not open serial port net. Is something else connected to the port? Did the port number or your computer change? Do you have permissions to the port?  Error Code: RE-FAST-1 (https://docs.missionpinball.org/en/dev/logs/RE-FAST-1.html)
2023-04-01 11:28:05,323 : INFO : root : MPF run loop ended.
