2024-02-01 15:57:29,011 : INFO : root : Loading config.
2024-02-01 15:57:29,015 : INFO : YamlMultifileConfigLoader : Machine config file #1: config.yaml
2024-02-01 15:57:29,016 : WARNING : ConfigProcessor : Config file in cache changed: C:\lofab\config\config.yaml
2024-02-01 15:57:29,016 : INFO : ConfigProcessor : Loading config from file C:\Users\Tanner\AppData\Local\Packages\PythonSoftwareFoundation.Python.3.11_qbz5n2kfra8p0\LocalCache\local-packages\Python311\site-packages\mpf\mpfconfig.yaml.
2024-02-01 15:57:29,027 : INFO : ConfigProcessor : Loading config: C:\Users\Tanner\AppData\Local\Packages\PythonSoftwareFoundation.Python.3.11_qbz5n2kfra8p0\LocalCache\local-packages\Python311\site-packages\mpf\mpfconfig.yaml
2024-02-01 15:57:29,027 : INFO : ConfigProcessor : Loading config from file C:\lofab\config\config.yaml.
2024-02-01 15:57:29,030 : INFO : ConfigProcessor : Loading config: C:\lofab\config\config.yaml
2024-02-01 15:57:29,031 : INFO : ConfigProcessor : Config file cache created: C:\Users\Tanner\AppData\Local\Temp\35bf7834a2cb30277765407e9f9dad35.mpf_cache
2024-02-01 15:57:29,110 : INFO : ConfigProcessor : Loading config from cache: C:\Users\Tanner\AppData\Local\Temp\165ae565642a148ddd3c4976ade4dd88.mpf_cache
2024-02-01 15:57:29,112 : INFO : ConfigProcessor : Loading config from cache: C:\Users\Tanner\AppData\Local\Temp\dfbe1b39ae456f06de73c859384050b2.mpf_cache
2024-02-01 15:57:29,112 : INFO : Machine : Mission Pinball Framework Core Engine v0.57.0.dev33
2024-02-01 15:57:29,113 : INFO : Machine : Command line arguments: {'no_load_cache': False, 'create_config_cache': True, 'bcp': False, 'configfile': ['config.yaml'], 'force_assets_load': False, 'jsonlogging': False, 'logfile': 'logs\\2024-02-01-15-57-29-mpf-DESKTOP-7HNFDQ5.log', 'pause': False, 'production': False, 'text_ui': True, 'loglevel': 15, 'consoleloglevel': 20, 'force_platform': None, 'syslog_address': None, 'mc_file_name': None, 'no_sound': False}
2024-02-01 15:57:29,113 : INFO : Machine : MPF path: C:\Users\Tanner\AppData\Local\Packages\PythonSoftwareFoundation.Python.3.11_qbz5n2kfra8p0\LocalCache\local-packages\Python311\site-packages\mpf
2024-02-01 15:57:29,113 : INFO : Machine : Machine path: C:\lofab
2024-02-01 15:57:29,113 : INFO : Machine : Platform: win32
2024-02-01 15:57:29,113 : INFO : Machine : Python executable location: C:\Users\Tanner\AppData\Local\Microsoft\WindowsApps\PythonSoftwareFoundation.Python.3.11_qbz5n2kfra8p0\python.exe
2024-02-01 15:57:29,113 : INFO : Machine : Python version: 3.11.7 (64-bit)
2024-02-01 15:57:29,116 : INFO : Machine : Initializing MPF...
2024-02-01 15:57:29,356 : INFO : [NET] : Trying to connect to com9 at 921600bps
2024-02-01 15:57:29,434 : INFO : [NET] : Connected to com9 at 921600bps
2024-02-01 15:57:29,444 : INFO : [NET] : Connected to FP-CPU-2000 with firmware v02.13
2024-02-01 15:57:29,475 : INFO : [NET] : Registered I/O Board 0: Model: FP-I/O-0804, Firmware: 01.10, Switches: 8, Drivers: 4
2024-02-01 15:57:29,490 : WARNING : [NET] : Interference / bad data received: b'NN:01,\xffP-I/O-0804-3   ,01.09,04,08,00,00,00,00,00,00'
2024-02-01 15:57:29,490 : ERROR : asyncio : Exception in callback Util.raise_exceptions(<Task finishe... start byte')>) at C:\Users\Tanner\AppData\Local\Packages\PythonSoftwareFoundation.Python.3.11_qbz5n2kfra8p0\LocalCache\local-packages\Python311\site-packages\mpf\core\utility_functions.py:784
handle: <Handle Util.raise_exceptions(<Task finishe... start byte')>) at C:\Users\Tanner\AppData\Local\Packages\PythonSoftwareFoundation.Python.3.11_qbz5n2kfra8p0\LocalCache\local-packages\Python311\site-packages\mpf\core\utility_functions.py:784>
Traceback (most recent call last):
  File "C:\Program Files\WindowsApps\PythonSoftwareFoundation.Python.3.11_3.11.2032.0_x64__qbz5n2kfra8p0\Lib\asyncio\events.py", line 80, in _run
    self._context.run(self._callback, *self._args)
  File "C:\Users\Tanner\AppData\Local\Packages\PythonSoftwareFoundation.Python.3.11_qbz5n2kfra8p0\LocalCache\local-packages\Python311\site-packages\mpf\core\utility_functions.py", line 792, in raise_exceptions
    future.result()
  File "C:\Users\Tanner\AppData\Local\Packages\PythonSoftwareFoundation.Python.3.11_qbz5n2kfra8p0\LocalCache\local-packages\Python311\site-packages\mpf\platforms\fast\communicators\base.py", line 373, in _socket_reader
    self.parse_incoming_raw_bytes(resp)
  File "C:\Users\Tanner\AppData\Local\Packages\PythonSoftwareFoundation.Python.3.11_qbz5n2kfra8p0\LocalCache\local-packages\Python311\site-packages\mpf\platforms\fast\communicators\base.py", line 325, in parse_incoming_raw_bytes
    msg = msg.decode()
          ^^^^^^^^^^^^
UnicodeDecodeError: 'utf-8' codec can't decode byte 0xff in position 6: invalid start byte
2024-02-01 15:57:29,492 : INFO : Machine : Starting the main run loop.
2024-02-01 15:57:29,496 : INFO : Machine : Shutting down...
2024-02-01 15:57:29,496 : INFO : EventManager : Event: ======'shutdown'====== Args={}
2024-02-01 15:57:30,598 : ERROR : Machine : Runtime Exception
Traceback (most recent call last):
  File "C:\Users\Tanner\AppData\Local\Packages\PythonSoftwareFoundation.Python.3.11_qbz5n2kfra8p0\LocalCache\local-packages\Python311\site-packages\mpf\core\machine.py", line 788, in _run_loop
    raise self._exception['exception']
  File "C:\Program Files\WindowsApps\PythonSoftwareFoundation.Python.3.11_3.11.2032.0_x64__qbz5n2kfra8p0\Lib\asyncio\events.py", line 80, in _run
    self._context.run(self._callback, *self._args)
  File "C:\Users\Tanner\AppData\Local\Packages\PythonSoftwareFoundation.Python.3.11_qbz5n2kfra8p0\LocalCache\local-packages\Python311\site-packages\mpf\core\utility_functions.py", line 792, in raise_exceptions
    future.result()
  File "C:\Users\Tanner\AppData\Local\Packages\PythonSoftwareFoundation.Python.3.11_qbz5n2kfra8p0\LocalCache\local-packages\Python311\site-packages\mpf\platforms\fast\communicators\base.py", line 373, in _socket_reader
    self.parse_incoming_raw_bytes(resp)
  File "C:\Users\Tanner\AppData\Local\Packages\PythonSoftwareFoundation.Python.3.11_qbz5n2kfra8p0\LocalCache\local-packages\Python311\site-packages\mpf\platforms\fast\communicators\base.py", line 325, in parse_incoming_raw_bytes
    msg = msg.decode()
          ^^^^^^^^^^^^
UnicodeDecodeError: 'utf-8' codec can't decode byte 0xff in position 6: invalid start byte
2024-02-01 15:57:30,600 : INFO : root : MPF run loop ended.
