2024-02-01 12:32:41,455 : INFO : root : Loading config.
2024-02-01 12:32:41,459 : INFO : YamlMultifileConfigLoader : Machine config file #1: config.yaml
2024-02-01 12:32:41,459 : WARNING : ConfigProcessor : Config file in cache changed: C:\lofab\config\config.yaml
2024-02-01 12:32:41,459 : INFO : ConfigProcessor : Loading config from file C:\Users\Tanner\AppData\Local\Packages\PythonSoftwareFoundation.Python.3.11_qbz5n2kfra8p0\LocalCache\local-packages\Python311\site-packages\mpf\mpfconfig.yaml.
2024-02-01 12:32:41,470 : INFO : ConfigProcessor : Loading config: C:\Users\Tanner\AppData\Local\Packages\PythonSoftwareFoundation.Python.3.11_qbz5n2kfra8p0\LocalCache\local-packages\Python311\site-packages\mpf\mpfconfig.yaml
2024-02-01 12:32:41,470 : INFO : ConfigProcessor : Loading config from file C:\lofab\config\config.yaml.
2024-02-01 12:32:41,473 : INFO : ConfigProcessor : Loading config: C:\lofab\config\config.yaml
2024-02-01 12:32:41,474 : INFO : ConfigProcessor : Config file cache created: C:\Users\Tanner\AppData\Local\Temp\35bf7834a2cb30277765407e9f9dad35.mpf_cache
2024-02-01 12:32:41,544 : INFO : ConfigProcessor : Loading config from cache: C:\Users\Tanner\AppData\Local\Temp\a2934b2c2ffee8b0382fdb4f299381ea.mpf_cache
2024-02-01 12:32:41,544 : INFO : ConfigProcessor : Loading config from cache: C:\Users\Tanner\AppData\Local\Temp\dfbe1b39ae456f06de73c859384050b2.mpf_cache
2024-02-01 12:32:41,545 : INFO : ConfigProcessor : Loading config from cache: C:\Users\Tanner\AppData\Local\Temp\ae8c868550a49a81e63b3815e7eb5a1d.mpf_cache
2024-02-01 12:32:41,546 : INFO : ConfigProcessor : Loading config from cache: C:\Users\Tanner\AppData\Local\Temp\33a505bd675d22be3af5a2b10c6c9794.mpf_cache
2024-02-01 12:32:41,546 : INFO : Machine : Mission Pinball Framework Core Engine v0.57.0.dev33
2024-02-01 12:32:41,547 : INFO : Machine : Command line arguments: {'no_load_cache': False, 'create_config_cache': True, 'bcp': False, 'configfile': ['config.yaml'], 'force_assets_load': False, 'jsonlogging': False, 'logfile': 'logs\\2024-02-01-12-32-41-mpf-DESKTOP-7HNFDQ5.log', 'pause': False, 'production': False, 'text_ui': True, 'loglevel': 15, 'consoleloglevel': 20, 'force_platform': None, 'syslog_address': None, 'mc_file_name': None, 'no_sound': False}
2024-02-01 12:32:41,547 : INFO : Machine : MPF path: C:\Users\Tanner\AppData\Local\Packages\PythonSoftwareFoundation.Python.3.11_qbz5n2kfra8p0\LocalCache\local-packages\Python311\site-packages\mpf
2024-02-01 12:32:41,547 : INFO : Machine : Machine path: C:\lofab
2024-02-01 12:32:41,547 : INFO : Machine : Platform: win32
2024-02-01 12:32:41,547 : INFO : Machine : Python executable location: C:\Users\Tanner\AppData\Local\Microsoft\WindowsApps\PythonSoftwareFoundation.Python.3.11_qbz5n2kfra8p0\python.exe
2024-02-01 12:32:41,547 : INFO : Machine : Python version: 3.11.7 (64-bit)
2024-02-01 12:32:41,549 : INFO : Machine : Initializing MPF...
2024-02-01 12:32:41,766 : INFO : [NET] : Trying to connect to com9 at 921600bps
2024-02-01 12:32:41,844 : INFO : [NET] : Connected to com9 at 921600bps
2024-02-01 12:32:41,853 : INFO : [NET] : Connected to FP-CPU-2000 with firmware v02.13
2024-02-01 12:32:41,885 : INFO : [NET] : Registered I/O Board 0: Model: FP-I/O-0804, Firmware: 01.10, Switches: 8, Drivers: 4
2024-02-01 12:32:41,901 : INFO : [NET] : Registered I/O Board 1: Model: FP-I/O-0804, Firmware: 01.09, Switches: 8, Drivers: 4
2024-02-01 12:32:41,916 : INFO : [NET] : Registered I/O Board 2: Model: FP-I/O-3208, Firmware: 01.10, Switches: 32, Drivers: 8
2024-02-01 12:32:41,917 : INFO : [EXP] : Trying to connect to com10 at 921600bps
2024-02-01 12:32:41,995 : INFO : [EXP] : Connected to com10 at 921600bps
2024-02-01 12:32:42,011 : INFO : [EXP] : Verifying hardware for EXP "pf" (FP-EXP-0081, @84) with ID string "EXP FP-EXP-0081  0.12", board address 84
2024-02-01 12:32:42,027 : INFO : [EXP] : Verifying hardware for EXP "pf" (FP-EXP-0081, @84) with ID string "BRK FP-EXP-0081  0.12", board address 840
2024-02-01 12:32:42,043 : INFO : [EXP] : Verifying hardware for EXP "pf" (FP-EXP-0081, @84) with ID string "BRK FP-EXP-0081  0.12", board address 841
2024-02-01 12:32:42,059 : INFO : EventManager : Event: ======'machine_var_credits_string'====== Args={'value': 'FREE PLAY', 'prev_value': None, 'change': True}
2024-02-01 12:32:42,073 : INFO : EventManager : Event: ======'machine_var_master_volume'====== Args={'value': 0.5, 'prev_value': None, 'change': True}
2024-02-01 12:32:42,073 : INFO : EventManager : Event: ======'machine_var_player1_score'====== Args={'value': 0, 'prev_value': None, 'change': True}
2024-02-01 12:32:42,073 : INFO : EventManager : Event: ======'machine_var_mpf_version'====== Args={'value': 'Mission Pinball Framework v0.57.0.dev33', 'prev_value': None, 'change': True}
2024-02-01 12:32:42,073 : INFO : EventManager : Event: ======'machine_var_mpf_extended_version'====== Args={'value': 'Mission Pinball Framework v0.57.0.dev33, Config version:6, Show version: 6, BCP version:1.1', 'prev_value': None, 'change': True}
2024-02-01 12:32:42,073 : INFO : EventManager : Event: ======'machine_var_python_version'====== Args={'value': '3.11.7', 'prev_value': None, 'change': True}
2024-02-01 12:32:42,081 : INFO : EventManager : Event: ======'machine_var_platform'====== Args={'value': 'Windows-10-10.0.19045-SP0', 'prev_value': None, 'change': True}
2024-02-01 12:32:42,081 : INFO : EventManager : Event: ======'machine_var_platform_system'====== Args={'value': 'Windows', 'prev_value': None, 'change': True}
2024-02-01 12:32:42,082 : INFO : EventManager : Event: ======'machine_var_platform_release'====== Args={'value': '10', 'prev_value': None, 'change': True}
2024-02-01 12:32:42,082 : INFO : EventManager : Event: ======'machine_var_platform_version'====== Args={'value': '10.0.19045', 'prev_value': None, 'change': True}
2024-02-01 12:32:42,082 : INFO : EventManager : Event: ======'machine_var_platform_machine'====== Args={'value': 'AMD64', 'prev_value': None, 'change': True}
2024-02-01 12:32:42,082 : INFO : EventManager : Event: ======'init_phase_1'====== Args={}
2024-02-01 12:32:42,092 : ERROR : asyncio : Exception in callback EventManager._async_handler_done(<QueuedEvent>)(<Task finishe...our config.')>) at C:\Users\Tanner\AppData\Local\Packages\PythonSoftwareFoundation.Python.3.11_qbz5n2kfra8p0\LocalCache\local-packages\Python311\site-packages\mpf\core\events.py:124
handle: <Handle EventManager._async_handler_done(<QueuedEvent>)(<Task finishe...our config.')>) at C:\Users\Tanner\AppData\Local\Packages\PythonSoftwareFoundation.Python.3.11_qbz5n2kfra8p0\LocalCache\local-packages\Python311\site-packages\mpf\core\events.py:124>
Traceback (most recent call last):
  File "C:\Program Files\WindowsApps\PythonSoftwareFoundation.Python.3.11_3.11.2032.0_x64__qbz5n2kfra8p0\Lib\asyncio\events.py", line 80, in _run
    self._context.run(self._callback, *self._args)
  File "C:\Users\Tanner\AppData\Local\Packages\PythonSoftwareFoundation.Python.3.11_qbz5n2kfra8p0\LocalCache\local-packages\Python311\site-packages\mpf\core\events.py", line 127, in _async_handler_done
    future.result()
  File "C:\Users\Tanner\AppData\Local\Packages\PythonSoftwareFoundation.Python.3.11_qbz5n2kfra8p0\LocalCache\local-packages\Python311\site-packages\mpf\core\device_manager.py", line 88, in _load_device_modules
    self.load_devices_config(validate=True)
  File "C:\Users\Tanner\AppData\Local\Packages\PythonSoftwareFoundation.Python.3.11_qbz5n2kfra8p0\LocalCache\local-packages\Python311\site-packages\mpf\core\device_manager.py", line 146, in load_devices_config
    config[device_name] = collection[device_name].validate_and_parse_config(config[device_name], False)
                          ^^^^^^^^^^^^^^^^^^^^^^^^^^^^^^^^^^^^^^^^^^^^^^^^^^^^^^^^^^^^^^^^^^^^^^^^^^^^^
  File "C:\Users\Tanner\AppData\Local\Packages\PythonSoftwareFoundation.Python.3.11_qbz5n2kfra8p0\LocalCache\local-packages\Python311\site-packages\mpf\core\device.py", line 108, in validate_and_parse_config
    self.machine.config_validator.validate_config(
  File "C:\Users\Tanner\AppData\Local\Packages\PythonSoftwareFoundation.Python.3.11_qbz5n2kfra8p0\LocalCache\local-packages\Python311\site-packages\mpf\core\config_validator.py", line 164, in validate_config
    return self._validate_config(config_spec, source, base_spec=base_spec, add_missing_keys=add_missing_keys,
           ^^^^^^^^^^^^^^^^^^^^^^^^^^^^^^^^^^^^^^^^^^^^^^^^^^^^^^^^^^^^^^^^^^^^^^^^^^^^^^^^^^^^^^^^^^^^^^^^^^
  File "C:\Users\Tanner\AppData\Local\Packages\PythonSoftwareFoundation.Python.3.11_qbz5n2kfra8p0\LocalCache\local-packages\Python311\site-packages\mpf\core\config_validator.py", line 205, in _validate_config
    processed_config[k] = self.validate_config_item(
                          ^^^^^^^^^^^^^^^^^^^^^^^^^^
  File "C:\Users\Tanner\AppData\Local\Packages\PythonSoftwareFoundation.Python.3.11_qbz5n2kfra8p0\LocalCache\local-packages\Python311\site-packages\mpf\core\config_validator.py", line 244, in validate_config_item
    return self.validate_item(item, validation, validation_failure_info)
           ^^^^^^^^^^^^^^^^^^^^^^^^^^^^^^^^^^^^^^^^^^^^^^^^^^^^^^^^^^^^^
  File "C:\Users\Tanner\AppData\Local\Packages\PythonSoftwareFoundation.Python.3.11_qbz5n2kfra8p0\LocalCache\local-packages\Python311\site-packages\mpf\core\config_validator.py", line 683, in validate_item
    return self.validator_list[validator](item, validation_failure_info=validation_failure_info, param=param)
           ^^^^^^^^^^^^^^^^^^^^^^^^^^^^^^^^^^^^^^^^^^^^^^^^^^^^^^^^^^^^^^^^^^^^^^^^^^^^^^^^^^^^^^^^^^^^^^^^^^
  File "C:\Users\Tanner\AppData\Local\Packages\PythonSoftwareFoundation.Python.3.11_qbz5n2kfra8p0\LocalCache\local-packages\Python311\site-packages\mpf\core\config_validator.py", line 401, in _validate_type_machine
    return self.validation_error(item, validation_failure_info,
           ^^^^^^^^^^^^^^^^^^^^^^^^^^^^^^^^^^^^^^^^^^^^^^^^^^^^
  File "C:\Users\Tanner\AppData\Local\Packages\PythonSoftwareFoundation.Python.3.11_qbz5n2kfra8p0\LocalCache\local-packages\Python311\site-packages\mpf\core\config_validator.py", line 700, in validation_error
    raise ConfigFileError("Config validation error: Entry {} = \"{}\" is not valid. {}".format(
mpf.exceptions.config_file_error.ConfigFileError: Config File Error in ConfigValidator: Config validation error: Entry playfields:playfield:default_source_device = "bd_trough" is not valid. Device "bd_trough" not found in "ball_devices:" section in your config. Error Code: CFE-ConfigValidator-6 (https://missionpinball.org/logs)
2024-02-01 12:32:42,094 : INFO : Machine : Starting the main run loop.
2024-02-01 12:32:42,097 : INFO : Machine : Shutting down...
2024-02-01 12:32:42,097 : INFO : EventManager : Event: ======'shutdown'====== Args={}
2024-02-01 12:32:43,206 : ERROR : Machine : Runtime Exception
Traceback (most recent call last):
  File "C:\Users\Tanner\AppData\Local\Packages\PythonSoftwareFoundation.Python.3.11_qbz5n2kfra8p0\LocalCache\local-packages\Python311\site-packages\mpf\core\machine.py", line 788, in _run_loop
    raise self._exception['exception']
  File "C:\Program Files\WindowsApps\PythonSoftwareFoundation.Python.3.11_3.11.2032.0_x64__qbz5n2kfra8p0\Lib\asyncio\events.py", line 80, in _run
    self._context.run(self._callback, *self._args)
  File "C:\Users\Tanner\AppData\Local\Packages\PythonSoftwareFoundation.Python.3.11_qbz5n2kfra8p0\LocalCache\local-packages\Python311\site-packages\mpf\core\events.py", line 127, in _async_handler_done
    future.result()
  File "C:\Users\Tanner\AppData\Local\Packages\PythonSoftwareFoundation.Python.3.11_qbz5n2kfra8p0\LocalCache\local-packages\Python311\site-packages\mpf\core\device_manager.py", line 88, in _load_device_modules
    self.load_devices_config(validate=True)
  File "C:\Users\Tanner\AppData\Local\Packages\PythonSoftwareFoundation.Python.3.11_qbz5n2kfra8p0\LocalCache\local-packages\Python311\site-packages\mpf\core\device_manager.py", line 146, in load_devices_config
    config[device_name] = collection[device_name].validate_and_parse_config(config[device_name], False)
                          ^^^^^^^^^^^^^^^^^^^^^^^^^^^^^^^^^^^^^^^^^^^^^^^^^^^^^^^^^^^^^^^^^^^^^^^^^^^^^
  File "C:\Users\Tanner\AppData\Local\Packages\PythonSoftwareFoundation.Python.3.11_qbz5n2kfra8p0\LocalCache\local-packages\Python311\site-packages\mpf\core\device.py", line 108, in validate_and_parse_config
    self.machine.config_validator.validate_config(
  File "C:\Users\Tanner\AppData\Local\Packages\PythonSoftwareFoundation.Python.3.11_qbz5n2kfra8p0\LocalCache\local-packages\Python311\site-packages\mpf\core\config_validator.py", line 164, in validate_config
    return self._validate_config(config_spec, source, base_spec=base_spec, add_missing_keys=add_missing_keys,
           ^^^^^^^^^^^^^^^^^^^^^^^^^^^^^^^^^^^^^^^^^^^^^^^^^^^^^^^^^^^^^^^^^^^^^^^^^^^^^^^^^^^^^^^^^^^^^^^^^^
  File "C:\Users\Tanner\AppData\Local\Packages\PythonSoftwareFoundation.Python.3.11_qbz5n2kfra8p0\LocalCache\local-packages\Python311\site-packages\mpf\core\config_validator.py", line 205, in _validate_config
    processed_config[k] = self.validate_config_item(
                          ^^^^^^^^^^^^^^^^^^^^^^^^^^
  File "C:\Users\Tanner\AppData\Local\Packages\PythonSoftwareFoundation.Python.3.11_qbz5n2kfra8p0\LocalCache\local-packages\Python311\site-packages\mpf\core\config_validator.py", line 244, in validate_config_item
    return self.validate_item(item, validation, validation_failure_info)
           ^^^^^^^^^^^^^^^^^^^^^^^^^^^^^^^^^^^^^^^^^^^^^^^^^^^^^^^^^^^^^
  File "C:\Users\Tanner\AppData\Local\Packages\PythonSoftwareFoundation.Python.3.11_qbz5n2kfra8p0\LocalCache\local-packages\Python311\site-packages\mpf\core\config_validator.py", line 683, in validate_item
    return self.validator_list[validator](item, validation_failure_info=validation_failure_info, param=param)
           ^^^^^^^^^^^^^^^^^^^^^^^^^^^^^^^^^^^^^^^^^^^^^^^^^^^^^^^^^^^^^^^^^^^^^^^^^^^^^^^^^^^^^^^^^^^^^^^^^^
  File "C:\Users\Tanner\AppData\Local\Packages\PythonSoftwareFoundation.Python.3.11_qbz5n2kfra8p0\LocalCache\local-packages\Python311\site-packages\mpf\core\config_validator.py", line 401, in _validate_type_machine
    return self.validation_error(item, validation_failure_info,
           ^^^^^^^^^^^^^^^^^^^^^^^^^^^^^^^^^^^^^^^^^^^^^^^^^^^^
  File "C:\Users\Tanner\AppData\Local\Packages\PythonSoftwareFoundation.Python.3.11_qbz5n2kfra8p0\LocalCache\local-packages\Python311\site-packages\mpf\core\config_validator.py", line 700, in validation_error
    raise ConfigFileError("Config validation error: Entry {} = \"{}\" is not valid. {}".format(
mpf.exceptions.config_file_error.ConfigFileError: Config File Error in ConfigValidator: Config validation error: Entry playfields:playfield:default_source_device = "bd_trough" is not valid. Device "bd_trough" not found in "ball_devices:" section in your config. Error Code: CFE-ConfigValidator-6 (https://missionpinball.org/logs)
2024-02-01 12:32:43,209 : INFO : root : MPF run loop ended.
