2024-02-03 18:22:48,485 : INFO : root : Loading config.
2024-02-03 18:22:48,489 : INFO : YamlMultifileConfigLoader : Machine config file #1: config.yaml
2024-02-03 18:22:48,490 : INFO : ConfigProcessor : Loading config from cache: C:\Users\Tanner\AppData\Local\Temp\ae594c12e5b61ed7124eed45950049a7.mpf_cache
2024-02-03 18:22:48,569 : INFO : ConfigProcessor : Loading config from cache: C:\Users\Tanner\AppData\Local\Temp\e981666969e170eb9e0a37595fe7075e.mpf_cache
2024-02-03 18:22:48,569 : INFO : ConfigProcessor : Loading config from cache: C:\Users\Tanner\AppData\Local\Temp\dfbe1b39ae456f06de73c859384050b2.mpf_cache
2024-02-03 18:22:48,571 : INFO : ConfigProcessor : Loading config from cache: C:\Users\Tanner\AppData\Local\Temp\e981666969e170eb9e0a37595fe7075e.mpf_cache
2024-02-03 18:22:48,572 : INFO : ConfigProcessor : Loading config from cache: C:\Users\Tanner\AppData\Local\Temp\408f6e4029d7abcf3040e9e16e1e62b0.mpf_cache
2024-02-03 18:22:48,578 : INFO : Machine : Mission Pinball Framework Core Engine v0.57.0.dev33
2024-02-03 18:22:48,578 : INFO : Machine : Command line arguments: {'no_load_cache': False, 'create_config_cache': True, 'bcp': False, 'configfile': ['config.yaml'], 'force_assets_load': False, 'jsonlogging': False, 'logfile': 'logs\\2024-02-03-18-22-48-mpf-DESKTOP-7HNFDQ5.log', 'pause': False, 'production': False, 'text_ui': True, 'loglevel': 15, 'consoleloglevel': 20, 'force_platform': None, 'syslog_address': None, 'mc_file_name': None, 'no_sound': False}
2024-02-03 18:22:48,578 : INFO : Machine : MPF path: C:\Users\Tanner\AppData\Local\Packages\PythonSoftwareFoundation.Python.3.11_qbz5n2kfra8p0\LocalCache\local-packages\Python311\site-packages\mpf
2024-02-03 18:22:48,578 : INFO : Machine : Machine path: c:\lofab
2024-02-03 18:22:48,578 : INFO : Machine : Platform: win32
2024-02-03 18:22:48,578 : INFO : Machine : Python executable location: C:\Users\Tanner\AppData\Local\Microsoft\WindowsApps\PythonSoftwareFoundation.Python.3.11_qbz5n2kfra8p0\python.exe
2024-02-03 18:22:48,579 : INFO : Machine : Python version: 3.11.7 (64-bit)
2024-02-03 18:22:48,580 : INFO : Machine : Initializing MPF...
2024-02-03 18:22:48,885 : INFO : [NET] : Trying to connect to com9 at 921600bps
2024-02-03 18:22:48,962 : INFO : [NET] : Connected to com9 at 921600bps
2024-02-03 18:22:48,974 : INFO : [NET] : Connected to FP-CPU-2000 with firmware v02.13
2024-02-03 18:22:49,006 : INFO : [NET] : Registered I/O Board 0: Model: FP-I/O-0804, Firmware: 01.10, Switches: 8, Drivers: 4
2024-02-03 18:22:49,021 : INFO : [NET] : Registered I/O Board 1: Model: FP-I/O-0804, Firmware: 01.09, Switches: 8, Drivers: 4
2024-02-03 18:22:49,036 : INFO : [NET] : Registered I/O Board 2: Model: FP-I/O-3208, Firmware: 01.10, Switches: 32, Drivers: 8
2024-02-03 18:22:49,037 : INFO : [EXP] : Trying to connect to com10 at 921600bps
2024-02-03 18:22:49,038 : ERROR : [EXP] : Failed to connect to any of the specified ports.
2024-02-03 18:22:49,041 : INFO : Machine : Shutting down...
2024-02-03 18:22:49,041 : INFO : EventManager : Event: ======'shutdown'====== Args={}
2024-02-03 18:22:49,132 : ERROR : Machine : Failed to initialize MPF
Traceback (most recent call last):
  File "C:\Users\Tanner\AppData\Local\Packages\PythonSoftwareFoundation.Python.3.11_qbz5n2kfra8p0\LocalCache\local-packages\Python311\site-packages\mpf\platforms\fast\fast.py", line 275, in _connect_to_hardware
    await communicator.connect()
  File "C:\Users\Tanner\AppData\Local\Packages\PythonSoftwareFoundation.Python.3.11_qbz5n2kfra8p0\LocalCache\local-packages\Python311\site-packages\mpf\platforms\fast\communicators\base.py", line 107, in connect
    raise SerialException(f"{self} could not connect to a serial port. Is it open in CoolTerm? ;)")
serial.serialutil.SerialException: [FAST EXP] could not connect to a serial port. Is it open in CoolTerm? ;)

The above exception was the direct cause of the following exception:

Traceback (most recent call last):
  File "C:\Users\Tanner\AppData\Local\Packages\PythonSoftwareFoundation.Python.3.11_qbz5n2kfra8p0\LocalCache\local-packages\Python311\site-packages\mpf\core\machine.py", line 670, in initialize_mpf
    raise init.exception()
  File "C:\Users\Tanner\AppData\Local\Packages\PythonSoftwareFoundation.Python.3.11_qbz5n2kfra8p0\LocalCache\local-packages\Python311\site-packages\mpf\core\machine.py", line 246, in initialize
    await self.initialize_core_and_hardware()
  File "C:\Users\Tanner\AppData\Local\Packages\PythonSoftwareFoundation.Python.3.11_qbz5n2kfra8p0\LocalCache\local-packages\Python311\site-packages\mpf\core\machine.py", line 242, in initialize_core_and_hardware
    await self._initialize_platforms()
  File "C:\Users\Tanner\AppData\Local\Packages\PythonSoftwareFoundation.Python.3.11_qbz5n2kfra8p0\LocalCache\local-packages\Python311\site-packages\mpf\core\machine.py", line 333, in _initialize_platforms
    result.result()
  File "C:\Users\Tanner\AppData\Local\Packages\PythonSoftwareFoundation.Python.3.11_qbz5n2kfra8p0\LocalCache\local-packages\Python311\site-packages\mpf\platforms\fast\fast.py", line 120, in initialize
    await self._connect_to_hardware()
  File "C:\Users\Tanner\AppData\Local\Packages\PythonSoftwareFoundation.Python.3.11_qbz5n2kfra8p0\LocalCache\local-packages\Python311\site-packages\mpf\platforms\fast\fast.py", line 281, in _connect_to_hardware
    raise MpfRuntimeError("Could not open serial port {}. Is something else connected to the port? "
mpf.exceptions.runtime_error.MpfRuntimeError: Runtime Error in FAST: Could not open serial port exp. Is something else connected to the port? Did the port number or your computer change? Do you have permissions to the port?  Error Code: RE-FAST-1 (https://missionpinball.org/logs)
2024-02-03 18:22:49,139 : INFO : root : MPF run loop ended.
